  0%|                                                                                                                                                                                     | 0/7434 [00:00<?, ?it/s]Traceback (most recent call last):
  File "/home/ubuntu/empath/finetune/finetune_falcon2.py", line 102, in <module>
    trainer.train()
  File "/home/ubuntu/empath/finetune/venv/lib/python3.10/site-packages/transformers/trainer.py", line 1539, in train
    return inner_training_loop(
  File "/home/ubuntu/empath/finetune/venv/lib/python3.10/site-packages/transformers/trainer.py", line 1787, in _inner_training_loop
    for step, inputs in enumerate(epoch_iterator):
  File "/home/ubuntu/empath/finetune/venv/lib/python3.10/site-packages/accelerate/data_loader.py", line 384, in __iter__
    current_batch = next(dataloader_iter)
  File "/home/ubuntu/empath/finetune/venv/lib/python3.10/site-packages/torch/utils/data/dataloader.py", line 633, in __next__
    data = self._next_data()
  File "/home/ubuntu/empath/finetune/venv/lib/python3.10/site-packages/torch/utils/data/dataloader.py", line 677, in _next_data
    data = self._dataset_fetcher.fetch(index)  # may raise StopIteration
  File "/home/ubuntu/empath/finetune/venv/lib/python3.10/site-packages/torch/utils/data/_utils/fetch.py", line 49, in fetch
    data = self.dataset.__getitems__(possibly_batched_index)
  File "/home/ubuntu/empath/finetune/venv/lib/python3.10/site-packages/datasets/arrow_dataset.py", line 2796, in __getitems__
    batch = self.__getitem__(keys)
  File "/home/ubuntu/empath/finetune/venv/lib/python3.10/site-packages/datasets/arrow_dataset.py", line 2792, in __getitem__
    return self._getitem(key)
  File "/home/ubuntu/empath/finetune/venv/lib/python3.10/site-packages/datasets/arrow_dataset.py", line 2776, in _getitem
    pa_subtable = query_table(self._data, key, indices=self._indices if self._indices is not None else None)
  File "/home/ubuntu/empath/finetune/venv/lib/python3.10/site-packages/datasets/formatting/formatting.py", line 583, in query_table
    _check_valid_index_key(key, size)
  File "/home/ubuntu/empath/finetune/venv/lib/python3.10/site-packages/datasets/formatting/formatting.py", line 536, in _check_valid_index_key
    _check_valid_index_key(int(max(key)), size=size)
  File "/home/ubuntu/empath/finetune/venv/lib/python3.10/site-packages/datasets/formatting/formatting.py", line 526, in _check_valid_index_key
    raise IndexError(f"Invalid key: {key} is out of bounds for size {size}")
IndexError: Invalid key: 19533 is out of bounds for size 0